<?xml version="1.0"?>
<robot name="iiwa_agv" xmlns:xacro="http://wiki.ros.org/xacro">

  <!-- some xacro properties-->
  <xacro:property name="PI" value="3.1415926535897931" />
  <xacro:property name="prefix" value="" />
  <xacro:property name="agv_mass" value="50.0" />
  <xacro:property name="shengjiang_mass" value="10.0" />
  <xacro:property name="xiao_arm_offset_x" value="0.15" />
  <xacro:property name="xiao_arm_offset_y" value="0.5" />
  <xacro:property name="initial_x" value="0.0" />
  <xacro:property name="initial_y" value="1.5" />

  <!-- include the xacro files-->
  <xacro:include filename="$(find iiwa_agv)/urdf/iiwa_agv.transmission.xacro"/>
  <xacro:include filename="$(find iiwa_agv)/urdf/iiwa_agv.gazebo.xacro"/>
  <xacro:include filename="$(find iiwa_agv)/urdf/materials.xacro"/>

  <!-- some xacro macros-->
  <xacro:macro name="cylinder_inertial" params="radius length mass *origin">
    <inertial>
      <mass value="${mass}" />
      <xacro:insert_block name="origin" />
      <inertia ixx="${0.0833333 * mass * (3 * radius * radius + length * length)}" ixy="0.0" ixz="0.0"
        iyy="${0.0833333 * mass * (3 * radius * radius + length * length)}" iyz="0.0"
        izz="${0.5 * mass * radius * radius}" />
    </inertial>
  </xacro:macro>


  <!-- link list -->
    
    <link name="world"/>
    
    <link name="${prefix}virtual_base">
        <inertial>
            <origin xyz="0.0 0.0 0.0" rpy="0.0 0.0 0.0"/>
            <mass value="1"/>
            <inertia ixx="1" ixy="0.0" ixz="0.0" iyy="1" iyz="0.0" izz="1"/>
        </inertial>
    </link>

    <link name="${prefix}virtual_x">
        <inertial>
            <origin xyz="0.0 0.0 0.0" rpy="0.0 0.0 0.0"/>
            <mass value="1"/>
            <inertia ixx="1" ixy="0.0" ixz="0.0" iyy="1" iyz="0.0" izz="1"/>
        </inertial>
    </link>

    <link name="${prefix}virtual_y">
        <inertial>
            <origin xyz="0.0 0.0 0.0" rpy="0.0 0.0 0.0"/>
            <mass value="1"/>
            <inertia ixx="1" ixy="0.0" ixz="0.0" iyy="1" iyz="0.0" izz="1"/>
        </inertial>
    </link>

    <joint name="world_base" type="fixed">
      <origin xyz="${initial_x} ${initial_y} 0.0" rpy="0.0 0.0 0.0"/>
      <parent link="world"/>
      <child link="${prefix}virtual_base"/>
    </joint>
    
    <joint name="${prefix}base_x" type="prismatic">
        <origin xyz="0.0 0.0 0.05" rpy="0.0 0.0 0.0"/>
        <parent link="${prefix}virtual_base"/>
        <child link="${prefix}virtual_x"/>
        <axis xyz="1.0 0.0 0.0"/>
        <limit lower="-5.0" upper="5.0" effort="50.0" velocity="2.0"/>
    </joint>
    <joint name="${prefix}x_y" type="prismatic">
        <origin xyz="0.0 0.0 0.0" rpy="0.0 0.0 0.0"/>
        <parent link="${prefix}virtual_x"/>
        <child link="${prefix}virtual_y"/>
        <axis xyz="0.0 1.0 0.0"/>
        <limit lower="-5.0" upper="5.0" effort="50.0" velocity="2.0"/>
    </joint>
    <joint name="${prefix}y_car" type="continuous">
        <origin xyz="0.0 0.0 0.0" rpy="0.0 0.0 0.0"/>
        <parent link="${prefix}virtual_y"/>
        <child link="${prefix}agv_link"/>
        <axis xyz="0.0 0.0 1.0"/>
        <limit effort="50.0" velocity="2.0"/>
    </joint>



  <link name="${prefix}agv_link">
    <inertial>
      <mass value="${agv_mass}" />
      <inertia ixx="${agv_mass}" ixy="0.0" ixz="0.0" iyy="${agv_mass}" iyz="0.0" izz="${agv_mass}" />
    </inertial>
    <visual>
      <origin xyz="0 0 0" rpy="${PI/2.0} 0 0" />
      <geometry>
        <mesh filename="package://iiwa_agv/meshes/car.STL" />
      </geometry>
      <material name="blue"/>
    </visual>
    <collision>
      <origin xyz="0 0 0" rpy="${PI/2.0} 0 0" />
      <geometry>
        <mesh filename="package://iiwa_agv/meshes/car.STL" />
      </geometry>
    </collision>
  </link>

  <link name="${prefix}control_box">
    <inertial>
      <mass value="23" />
      <inertia ixx="1" ixy="0.0" ixz="0.0" iyy="1" iyz="0.0" izz="1" />
    </inertial>
    <visual>
      <origin xyz="0 0 0" rpy="0 0 0" />
      <geometry>
        <box size="0.5 0.483 0.19"/>
      </geometry>
      <material name="blue"/>
    </visual>
    <collision>
      <origin xyz="0 0 0" rpy="0 0 0" />
      <geometry>
        <box size="0.5 0.483 0.19"/>
      </geometry>
    </collision>
  </link>


  <link name="${prefix}base_link">
    <visual>
      <origin xyz="0 0 0" rpy="0 0 0" />
      <geometry>
        <mesh filename="package://iiwa_agv/meshes/lbr_iiwa_14_r820/visual/base_link.dae" />
      </geometry>
      <material name="purple"/>
    </visual>
    <collision>
      <origin xyz="0 0 0" rpy="0 0 0" />
      <geometry>
        <mesh filename="package://iiwa_agv/meshes/lbr_iiwa_14_r820/collision/base_link.stl" />
      </geometry>
    </collision>
    <xacro:cylinder_inertial radius="0.075" length="0.038" mass="0.5">
      <origin xyz="0.0 0.0 0.0" rpy="0 0 0" />
    </xacro:cylinder_inertial>
  </link>

  <link name="${prefix}link_1">
    <visual>
      <origin xyz="0 0 0" rpy="0 0 0" />
      <geometry>
        <mesh filename="package://iiwa_agv/meshes/lbr_iiwa_14_r820/visual/link_1.dae" />
      </geometry>
      <material name="yellow"/>
    </visual>
    <collision>
      <origin xyz="0 0 0" rpy="0 0 0" />
      <geometry>
        <mesh filename="package://iiwa_agv/meshes/lbr_iiwa_14_r820/collision/link_1.stl" />
      </geometry>
    </collision>
    <xacro:cylinder_inertial radius="0.075" length="0.038" mass="0.5">
      <origin xyz="0.0 0.0 0.0" rpy="0 0 0" />
    </xacro:cylinder_inertial>
  </link>

  <link name="${prefix}link_2">
    <visual>
      <origin xyz="0 0 0" rpy="0 0 0" />
      <geometry>
        <mesh filename="package://iiwa_agv/meshes/lbr_iiwa_14_r820/visual/link_2.dae" />
      </geometry>
      <material name="red"/>
    </visual>
    <collision>
      <origin xyz="0 0 0" rpy="0 0 0" />
      <geometry>
        <mesh filename="package://iiwa_agv/meshes/lbr_iiwa_14_r820/collision/link_2.stl" />
      </geometry>
    </collision>
    <xacro:cylinder_inertial radius="0.075" length="0.038" mass="0.5">
      <origin xyz="0.0 0.0 0.0" rpy="0 0 0" />
    </xacro:cylinder_inertial>
  </link>

  <link name="${prefix}link_3">
    <visual>
      <origin xyz="0 0 0" rpy="0 0 0" />
      <geometry>
        <mesh filename="package://iiwa_agv/meshes/lbr_iiwa_14_r820/visual/link_3.dae" />
      </geometry>
      <material name="orange"/>
    </visual>
    <collision>
      <origin xyz="0 0 0" rpy="0 0 0" />
      <geometry>
        <mesh filename="package://iiwa_agv/meshes/lbr_iiwa_14_r820/collision/link_3.stl" />
      </geometry>
    </collision>
    <xacro:cylinder_inertial radius="0.075" length="0.038" mass="0.5">
      <origin xyz="0.0 0.0 0.0" rpy="0 0 0" />
    </xacro:cylinder_inertial>
  </link>

  <link name="${prefix}link_4">
    <visual>
      <origin xyz="0 0 0" rpy="0 0 0" />
      <geometry>
        <mesh filename="package://iiwa_agv/meshes/lbr_iiwa_14_r820/visual/link_4.dae" />
      </geometry>
      <material name="grey"/>
    </visual>
    <collision>
      <origin xyz="0 0 0" rpy="0 0 0" />
      <geometry>
        <mesh filename="package://iiwa_agv/meshes/lbr_iiwa_14_r820/collision/link_4.stl" />
      </geometry>
    </collision>
    <xacro:cylinder_inertial radius="0.075" length="0.038" mass="0.5">
      <origin xyz="0.0 0.0 0.0" rpy="0 0 0" />
    </xacro:cylinder_inertial>
  </link>

  <link name="${prefix}link_5">
    <visual>
      <origin xyz="0 0 0" rpy="0 0 0" />
      <geometry>
        <mesh filename="package://iiwa_agv/meshes/lbr_iiwa_14_r820/visual/link_5.dae" />
      </geometry>
      <material name="green"/>
    </visual>
    <collision>
      <origin xyz="0 0 0" rpy="0 0 0" />
      <geometry>
        <mesh filename="package://iiwa_agv/meshes/lbr_iiwa_14_r820/collision/link_5.stl" />
      </geometry>
    </collision>
    <xacro:cylinder_inertial radius="0.075" length="0.038" mass="0.5">
      <origin xyz="0.0 0.0 0.0" rpy="0 0 0" />
    </xacro:cylinder_inertial>
  </link>

  <link name="${prefix}link_6">
    <visual>
      <origin xyz="0 0 0" rpy="0 0 0" />
      <geometry>
        <mesh filename="package://iiwa_agv/meshes/lbr_iiwa_14_r820/visual/link_6.dae" />
      </geometry>
      <material name="blue"/>
    </visual>
    <collision>
      <origin xyz="0 0 0" rpy="0 0 0" />
      <geometry>
        <mesh filename="package://iiwa_agv/meshes/lbr_iiwa_14_r820/collision/link_6.stl" />
      </geometry>
    </collision>
    <xacro:cylinder_inertial radius="0.075" length="0.038" mass="0.5">
      <origin xyz="0.0 0.0 0.0" rpy="0 0 0" />
    </xacro:cylinder_inertial>
  </link>

  <link name="${prefix}link_7">
    <visual>
      <origin xyz="0 0 0" rpy="0 0 0" />
      <geometry>
        <mesh filename="package://iiwa_agv/meshes/lbr_iiwa_14_r820/visual/link_7.dae" />
      </geometry>
      <material name="yellow"/>
    </visual>
    <collision>
      <origin xyz="0 0 0" rpy="0 0 0" />
      <geometry>
        <mesh filename="package://iiwa_agv/meshes/lbr_iiwa_14_r820/collision/link_7.stl" />
      </geometry>
    </collision>
    <xacro:cylinder_inertial radius="0.075" length="0.038" mass="0.5">
      <origin xyz="0.0 0.0 0.0" rpy="0 0 0" />
    </xacro:cylinder_inertial>
  </link>

  <link name="${prefix}tool0" />

  <link name="${prefix}pan_link">
    <visual>
      <origin xyz="0 0 0" rpy="0 0 0" />
      <geometry>
        <mesh filename="package://iiwa_agv/meshes/pan.STL"/>
      </geometry>
      <material name="black"/>
    </visual>
    <collision>
      <origin xyz="0 0 0" rpy="0 0 0" />
      <geometry>
        <mesh filename="package://iiwa_agv/meshes/pan.STL"/>
      </geometry>
    </collision>
    <xacro:cylinder_inertial radius="0.05" length="0.01" mass="0.01">
      <origin xyz="0.0 0.0 0.0" rpy="0 0 0" />
    </xacro:cylinder_inertial>
  </link>

  <link name="${prefix}falan">
    <visual>
      <origin xyz="0 0 0" rpy="0 0 0" />
      <geometry>
        <mesh filename="package://iiwa_agv/meshes/falan.STL"/>
      </geometry>
      <material name="white"/>
    </visual>
    <collision>
      <origin xyz="0 0 0" rpy="0 0 0" />
      <geometry>
        <mesh filename="package://iiwa_agv/meshes/falan.STL"/>
      </geometry>
    </collision>
    <inertial>
      <mass value="0.1" />
      <inertia ixx="0.1" ixy="0.0" ixz="0.0" iyy="0.1" iyz="0.0" izz="0.1" />
    </inertial>
  </link>

  <link name="${prefix}xiao_arm1_link">
    <visual>
      <origin xyz="0 0 0" rpy="0 0 0" />
      <geometry>
        <mesh filename="package://iiwa_agv/meshes/xiao_arm.STL"/>
      </geometry>
      <material name="white"/>
    </visual>
    <collision>
      <origin xyz="0 0 0" rpy="0 0 0" />
      <geometry>
        <mesh filename="package://iiwa_agv/meshes/xiao_arm.STL"/>
      </geometry>
    </collision>
    <xacro:cylinder_inertial radius="0.01" length="0.05" mass="0.01">
      <origin xyz="0.1 0.0 0.25" rpy="0 0 0" />
    </xacro:cylinder_inertial>
  </link>

  <link name="${prefix}xiao_arm2_link">
    <visual>
      <origin xyz="0 0 0" rpy="0 0 0" />
      <geometry>
        <mesh filename="package://iiwa_agv/meshes/xiao_arm.STL"/>
      </geometry>
      <material name="green"/>
    </visual>
    <collision>
      <origin xyz="0 0 0" rpy="0 0 0" />
      <geometry>
        <mesh filename="package://iiwa_agv/meshes/xiao_arm.STL"/>
      </geometry>
    </collision>
    <xacro:cylinder_inertial radius="0.01" length="0.05" mass="0.01">
      <origin xyz="-0.1 0.0 0.25" rpy="0 0 0" />
    </xacro:cylinder_inertial>
  </link>

  <link name="${prefix}xiangji_link">
    <visual>
      <origin xyz="0.0 0.0 0.0" rpy="0 0 0" />
      <geometry>
        <mesh filename="package://iiwa_agv/meshes/xiangji.STL"/>
      </geometry>
      <material name="orange"/>
    </visual>
    <collision>
      <origin xyz="0.0 0.0 0.07" rpy="0 0 0" />
      <geometry>
        <mesh filename="package://iiwa_agv/meshes/xiao_arm.STL"/>
      </geometry>
    </collision>
    <xacro:cylinder_inertial radius="0.01" length="0.05" mass="0.01">
      <origin xyz="0.0 0.0 0.0" rpy="0 0 0" />
    </xacro:cylinder_inertial>
  </link>

  <!-- end of link list -->

  <!-- joint list -->

  <joint name="${prefix}agv_to_base_joint" type="fixed">
    <origin xyz="-0.2 0 0.3" rpy="0 0 0" />
    <parent link="${prefix}agv_link" />
    <child link="${prefix}base_link" />
  </joint>

  <joint name="${prefix}agv_tocontrol_box" type="fixed">
    <origin xyz="0.35 0 0.41" rpy="0 0 0" />
    <parent link="${prefix}agv_link" />
    <child link="${prefix}control_box" />
  </joint>

  <joint name="${prefix}joint_a1" type="revolute">
    <origin xyz="0 0 0" rpy="0 0 0" />
    <parent link="${prefix}base_link" />
    <child link="${prefix}link_1" />
    <axis xyz="0 0 1" />
    <limit lower="-2.9668" upper="2.9668" effort="50" velocity="1.4834" />
  </joint>

  <joint name="${prefix}joint_a2" type="revolute">
    <origin xyz="-0.00043624 0 0.36" rpy="0 0 0" />
    <parent link="${prefix}link_1" />
    <child link="${prefix}link_2" />
    <axis xyz="0 1 0" />
    <limit lower="-2.0942" upper="2.0942" effort="50" velocity="1.4834" />
  </joint>

  <joint name="${prefix}joint_a3" type="revolute">
    <origin xyz="0 0 0" rpy="0 0 0" />
    <parent link="${prefix}link_2" />
    <child link="${prefix}link_3" />
    <axis xyz="0 0 1" />
    <limit lower="-2.9668" upper="2.9668" effort="50" velocity="1.7452" />
  </joint>

  <joint name="${prefix}joint_a4" type="revolute">
    <origin xyz="0.00043624 0 0.42" rpy="0 0 0" />
    <parent link="${prefix}link_3" />
    <child link="${prefix}link_4" />
    <axis xyz="0 -1 0" />
    <limit lower="-2.0942" upper="2.0942" effort="50" velocity="1.3089" />
  </joint>
  
  <joint name="${prefix}joint_a5" type="revolute">
    <origin xyz="0 0 0" rpy="0 0 0" />
    <parent link="${prefix}link_4" />
    <child link="${prefix}link_5" />
    <axis xyz="0 0 1" />
    <limit lower="-2.9668" upper="2.9668" effort="50" velocity="2.2688" />
  </joint>

  <joint name="${prefix}joint_a6" type="revolute">
    <origin xyz="0 0 0.4" rpy="0 0 0" />
    <parent link="${prefix}link_5" />
    <child link="${prefix}link_6" />
    <axis xyz="0 1 0" />
    <limit lower="-2.0942" upper="2.0942" effort="50" velocity="2.356" />
  </joint>

  <joint name="${prefix}joint_a7" type="revolute">
    <origin xyz="0 0 0" rpy="0 0 0" />
    <parent link="${prefix}link_6" />
    <child link="${prefix}link_7" />
    <axis xyz="0 0 1" />
    <limit lower="-3.0541" upper="3.0541" effort="50" velocity="2.356" />
  </joint>

  <joint name="${prefix}joint_a7-tool0" type="fixed">
    <origin xyz="0 0 0.126" rpy="0 0 0" />
    <parent link="${prefix}link_7" />
    <child link="${prefix}tool0" />
    <axis xyz="0 0 0" />
  </joint>

  <joint name="${prefix}link7_to_falan_joint" type="fixed">
    <parent link="${prefix}link_7" />
    <child link = "${prefix}falan" />
    <origin xyz="0.0 0.0 0.13" rpy="${-PI/2.0} 0.0 ${PI}" />
  </joint>

  <joint name="${prefix}falan_to_pan_joint" type="fixed">
    <parent link="${prefix}falan" />
    <child link = "${prefix}pan_link" />
    <origin xyz="0.11 0.0 0" rpy="${PI} 0.0 ${PI/2.0}" />
  </joint>

  <joint name="${prefix}pan_to_xiao_arm1_joint" type="fixed">
    <parent link="${prefix}pan_link" />
    <child link = "${prefix}xiao_arm1_link" />
    <origin xyz="0.0 0.0 -0.47" rpy="0.0 0.0 0.0" />
  </joint>

  <joint name="${prefix}pan_to_xiao_arm2_joint" type="fixed">
    <parent link="${prefix}pan_link" />
    <child link = "${prefix}xiao_arm2_link" />
    <origin xyz="-0.15 0.0 -0.47" rpy="0.0 0.0 0.0" />
  </joint>

  <joint name="${prefix}pan_to_xiangji_joint" type="fixed">
    <parent link="${prefix}pan_link" />
    <child link = "${prefix}xiangji_link" />
    <origin xyz="0.0 0.065 -0.1" rpy="-1.570796 0.0 0.0" />
  </joint>

  <!-- end of joint list -->

</robot>